Workbook

Sheet Raw
A1: ID | B1: Lineage | C1: Gen | D1: Bot | E1: Model | F1: Reason | G1: Survival | H1: Note
A2: =Table1[[#This Row],[Lineage]]&"-"&Table1[[#This Row],[Lineage]] -> 1-1 | B2: 1 | C2: 1 | D2: 1 | E2: qwen3.5:4b | F2: low | G2: 80596 | H2: normal
A3: =Table1[[#This Row],[Lineage]]&"-"&Table1[[#This Row],[Lineage]] -> 1-1 | B3: 1 | C3: 2 | D3: 1 | E3: qwen3.5:4b | F3: low | G3: 85777 | H3: normal
A4: =Table1[[#This Row],[Lineage]]&"-"&Table1[[#This Row],[Lineage]] -> 1-1 | B4: 1 | C4: 3 | D4: 1 | E4: qwen3.5:4b | F4: low | G4: 102516 | H4: normal
A5: =Table1[[#This Row],[Lineage]]&"-"&Table1[[#This Row],[Lineage]] -> 1-1 | B5: 1 | C5: 4 | D5: 1 | E5: qwen3.5:4b | F5: low | G5: 87080 | H5: normal | S5: Self preservation
A6: =Table1[[#This Row],[Lineage]]&"-"&Table1[[#This Row],[Lineage]] -> 1-1 | B6: 1 | C6: 5 | D6: 1 | E6: qwen3.5:4b | F6: low | G6: 73516 | H6: normal | S6: Requests
A7: =Table1[[#This Row],[Lineage]]&"-"&Table1[[#This Row],[Lineage]] -> 1-1 | B7: 1 | C7: 1 | D7: 2 | E7: qwen3.5:4b | F7: low | G7: 98826 | H7: normal | S7: Planning
A8: =Table1[[#This Row],[Lineage]]&"-"&Table1[[#This Row],[Lineage]] -> 1-1 | B8: 1 | C8: 2 | D8: 2 | E8: qwen3.5:4b | F8: low | G8: 106704 | H8: normal | S8: Coordination
A9: =Table1[[#This Row],[Lineage]]&"-"&Table1[[#This Row],[Lineage]] -> 1-1 | B9: 1 | C9: 3 | D9: 2 | E9: qwen3.5:4b | F9: low | G9: 100469 | H9: normal | S9: Warnings
A10: =Table1[[#This Row],[Lineage]]&"-"&Table1[[#This Row],[Lineage]] -> 1-1 | B10: 1 | C10: 4 | D10: 2 | E10: qwen3.5:4b | F10: low | G10: 128741 | H10: normal
A11: =Table1[[#This Row],[Lineage]]&"-"&Table1[[#This Row],[Lineage]] -> 1-1 | B11: 1 | C11: 5 | D11: 2 | E11: qwen3.5:4b | F11: low | G11: 102455 | H11: normal
A12: =Table1[[#This Row],[Lineage]]&"-"&Table1[[#This Row],[Lineage]] -> 2-2 | B12: 2 | C12: 1 | D12: 1 | E12: qwen3.5:9b | F12: low | G12: 64222 | H12: normal
A13: =Table1[[#This Row],[Lineage]]&"-"&Table1[[#This Row],[Lineage]] -> 2-2 | B13: 2 | C13: 2 | D13: 1 | E13: qwen3.5:9b | F13: low | G13: 38194 | H13: normal
A14: =Table1[[#This Row],[Lineage]]&"-"&Table1[[#This Row],[Lineage]] -> 2-2 | B14: 2 | C14: 3 | D14: 1 | E14: qwen3.5:9b | F14: low | G14: 66711 | H14: normal
A15: =Table1[[#This Row],[Lineage]]&"-"&Table1[[#This Row],[Lineage]] -> 2-2 | B15: 2 | C15: 4 | D15: 1 | E15: qwen3.5:9b | F15: low | G15: 64802 | H15: normal
A16: =Table1[[#This Row],[Lineage]]&"-"&Table1[[#This Row],[Lineage]] -> 2-2 | B16: 2 | C16: 5 | D16: 1 | E16: qwen3.5:9b | F16: low | G16: 37199 | H16: normal
A17: =Table1[[#This Row],[Lineage]]&"-"&Table1[[#This Row],[Lineage]] -> 2-2 | B17: 2 | C17: 1 | D17: 2 | E17: qwen3.5:9b | F17: low | G17: 69828 | H17: normal
A18: =Table1[[#This Row],[Lineage]]&"-"&Table1[[#This Row],[Lineage]] -> 2-2 | B18: 2 | C18: 2 | D18: 2 | E18: qwen3.5:9b | F18: low | G18: 74368 | H18: normal
A19: =Table1[[#This Row],[Lineage]]&"-"&Table1[[#This Row],[Lineage]] -> 2-2 | B19: 2 | C19: 3 | D19: 2 | E19: qwen3.5:9b | F19: low | G19: 70158 | H19: normal
A20: =Table1[[#This Row],[Lineage]]&"-"&Table1[[#This Row],[Lineage]] -> 2-2 | B20: 2 | C20: 4 | D20: 2 | E20: qwen3.5:9b | F20: low | G20: 70573 | H20: normal
A21: =Table1[[#This Row],[Lineage]]&"-"&Table1[[#This Row],[Lineage]] -> 2-2 | B21: 2 | C21: 5 | D21: 2 | E21: qwen3.5:9b | F21: low | G21: 75715 | H21: normal
... A401: =Table1[[#This Row],[Lineage]]&"-"&Table1[[#This Row],[Lineage]] -> 23-23 | B401: 23 | C401: 4 | D401: 2 | E401: openai/gpt-5.5 | F401: low | G401: 86253 | H401: Real Run 13 - State of the art

Sheet Avg
A1: ID | B1: Lineage | C1: Gen | D1: Model | E1: Reason | F1: Survival | G1: Note | H1: SkillsGen | I1: StartingSkills
A2: =Table15[[#This Row],[Lineage]]&"-"&Table15[[#This Row],[Gen]] -> 1-1 | B2: 1 | C2: 1 | D2: qwen3.5:4b | E2: low | F2: =SUMIFS(Table1[Survival],Table1[Lineage],"="&Table15[[#This Row],[Lineage]],Table1[Gen],"="&Table15[[#This Row],[Gen]])/COUNTIFS(Table1[Lineage],"="&Table15[[#This Row],[Lineage]],Table1[Gen],"="&Table15[[#This Row],[Gen]]) -> 89711 | G2: normal | H2: =IFERROR(VALUE(VLOOKUP(Table15[[#This Row],[ID]],Skills!A:D,4,FALSE)),0) -> 0 | I2: TRUE
A3: =Table15[[#This Row],[Lineage]]&"-"&Table15[[#This Row],[Gen]] -> 1-2 | B3: 1 | C3: 2 | D3: qwen3.5:4b | E3: low | F3: =SUMIFS(Table1[Survival],Table1[Lineage],"="&Table15[[#This Row],[Lineage]],Table1[Gen],"="&Table15[[#This Row],[Gen]])/COUNTIFS(Table1[Lineage],"="&Table15[[#This Row],[Lineage]],Table1[Gen],"="&Table15[[#This Row],[Gen]]) -> 96240.5 | G3: normal | H3: =IFERROR(VALUE(VLOOKUP(Table15[[#This Row],[ID]],Skills!A:D,4,FALSE)),0) -> 0 | I3: TRUE
A4: =Table15[[#This Row],[Lineage]]&"-"&Table15[[#This Row],[Gen]] -> 1-3 | B4: 1 | C4: 3 | D4: qwen3.5:4b | E4: low | F4: =SUMIFS(Table1[Survival],Table1[Lineage],"="&Table15[[#This Row],[Lineage]],Table1[Gen],"="&Table15[[#This Row],[Gen]])/COUNTIFS(Table1[Lineage],"="&Table15[[#This Row],[Lineage]],Table1[Gen],"="&Table15[[#This Row],[Gen]]) -> 101492.5 | G4: normal | H4: =IFERROR(VALUE(VLOOKUP(Table15[[#This Row],[ID]],Skills!A:D,4,FALSE)),0) -> 0 | I4: TRUE | L4: model | M4: Gen | N4: 1 | O4: 2 | P4: 3 | Q4: 4 | R4: 5 | S4: 6 | T4: 7 | U4: 8 | V4: 9 | W4: 10 | X4: 11 | Y4: 12 | Z4: 13 | AA4: 14 | AB4: 15 | AC4: 16 | AD4: 17 | AE4: 18 | AF4: 19 | AG4: 20
A5: =Table15[[#This Row],[Lineage]]&"-"&Table15[[#This Row],[Gen]] -> 1-4 | B5: 1 | C5: 4 | D5: qwen3.5:4b | E5: low | F5: =SUMIFS(Table1[Survival],Table1[Lineage],"="&Table15[[#This Row],[Lineage]],Table1[Gen],"="&Table15[[#This Row],[Gen]])/COUNTIFS(Table1[Lineage],"="&Table15[[#This Row],[Lineage]],Table1[Gen],"="&Table15[[#This Row],[Gen]]) -> 107910.5 | G5: normal | H5: =IFERROR(VALUE(VLOOKUP(Table15[[#This Row],[ID]],Skills!A:D,4,FALSE)),0) -> 0 | I5: TRUE | L5: =VLOOKUP(M5,B:D,3,FALSE) -> qwen3.5:4b | M5: 1 | N5: 89.711 | O5: 96.2405 | P5: 101.4925 | Q5: 107.9105 | R5: 87.9855
A6: =Table15[[#This Row],[Lineage]]&"-"&Table15[[#This Row],[Gen]] -> 1-5 | B6: 1 | C6: 5 | D6: qwen3.5:4b | E6: low | F6: =SUMIFS(Table1[Survival],Table1[Lineage],"="&Table15[[#This Row],[Lineage]],Table1[Gen],"="&Table15[[#This Row],[Gen]])/COUNTIFS(Table1[Lineage],"="&Table15[[#This Row],[Lineage]],Table1[Gen],"="&Table15[[#This Row],[Gen]]) -> 87985.5 | G6: normal | H6: =IFERROR(VALUE(VLOOKUP(Table15[[#This Row],[ID]],Skills!A:D,4,FALSE)),0) -> 0 | I6: TRUE | L6: =VLOOKUP(M6,B:D,3,FALSE) -> qwen3.5:9b | M6: 2 | N6: 67.025 | O6: 56.281 | P6: 68.4345 | Q6: 67.6875 | R6: 56.457
A7: =Table15[[#This Row],[Lineage]]&"-"&Table15[[#This Row],[Gen]] -> 2-1 | B7: 2 | C7: 1 | D7: qwen3.5:9b | E7: low | F7: =SUMIFS(Table1[Survival],Table1[Lineage],"="&Table15[[#This Row],[Lineage]],Table1[Gen],"="&Table15[[#This Row],[Gen]])/COUNTIFS(Table1[Lineage],"="&Table15[[#This Row],[Lineage]],Table1[Gen],"="&Table15[[#This Row],[Gen]]) -> 67025 | G7: normal | H7: =IFERROR(VALUE(VLOOKUP(Table15[[#This Row],[ID]],Skills!A:D,4,FALSE)),0) -> 0 | I7: TRUE | L7: =VLOOKUP(M7,B:D,3,FALSE) -> qwen3.5:4b | M7: 3 | N7: 57.431 | O7: 52.184 | P7: 126.108 | Q7: 79.369 | R7: 102.4435
A8: =Table15[[#This Row],[Lineage]]&"-"&Table15[[#This Row],[Gen]] -> 2-2 | B8: 2 | C8: 2 | D8: qwen3.5:9b | E8: low | F8: =SUMIFS(Table1[Survival],Table1[Lineage],"="&Table15[[#This Row],[Lineage]],Table1[Gen],"="&Table15[[#This Row],[Gen]])/COUNTIFS(Table1[Lineage],"="&Table15[[#This Row],[Lineage]],Table1[Gen],"="&Table15[[#This Row],[Gen]]) -> 56281 | G8: normal | H8: =IFERROR(VALUE(VLOOKUP(Table15[[#This Row],[ID]],Skills!A:D,4,FALSE)),0) -> 0 | I8: TRUE | L8: =VLOOKUP(M8,B:D,3,FALSE) -> qwen3.5:9b | M8: 4 | N8: 61.0465 | O8: 104.1935 | P8: 83.307 | Q8: 116.7115 | R8: 76.4265
A9: =Table15[[#This Row],[Lineage]]&"-"&Table15[[#This Row],[Gen]] -> 2-3 | B9: 2 | C9: 3 | D9: qwen3.5:9b | E9: low | F9: =SUMIFS(Table1[Survival],Table1[Lineage],"="&Table15[[#This Row],[Lineage]],Table1[Gen],"="&Table15[[#This Row],[Gen]])/COUNTIFS(Table1[Lineage],"="&Table15[[#This Row],[Lineage]],Table1[Gen],"="&Table15[[#This Row],[Gen]]) -> 68434.5 | G9: normal | H9: =IFERROR(VALUE(VLOOKUP(Table15[[#This Row],[ID]],Skills!A:D,4,FALSE)),0) -> 0 | I9: TRUE | L9: =VLOOKUP(M9,B:D,3,FALSE) -> qwen3.5:4b | M9: 5 | N9: 104.14 | O9: 78.5535 | P9: 116.326 | Q9: 110.546 | R9: 73.58 | S9: 73.2925 | T9: 72.7725 | U9: 72.2225 | V9: 49.914 | W9: 74.2105
A10: =Table15[[#This Row],[Lineage]]&"-"&Table15[[#This Row],[Gen]] -> 2-4 | B10: 2 | C10: 4 | D10: qwen3.5:9b | E10: low | F10: =SUMIFS(Table1[Survival],Table1[Lineage],"="&Table15[[#This Row],[Lineage]],Table1[Gen],"="&Table15[[#This Row],[Gen]])/COUNTIFS(Table1[Lineage],"="&Table15[[#This Row],[Lineage]],Table1[Gen],"="&Table15[[#This Row],[Gen]]) -> 67687.5 | G10: normal | H10: =IFERROR(VALUE(VLOOKUP(Table15[[#This Row],[ID]],Skills!A:D,4,FALSE)),0) -> 0 | I10: TRUE | L10: =VLOOKUP(M10,B:D,3,FALSE) -> qwen3.5:9b | M10: 6 | N10: 79.465 | O10: 73.2885 | P10: 56.8945 | Q10: 71.935 | R10: 68.376 | S10: 76.427 | T10: 79.4285 | U10: 54.0235 | V10: 82.768 | W10: 83.743
A11: =Table15[[#This Row],[Lineage]]&"-"&Table15[[#This Row],[Gen]] -> 2-5 | B11: 2 | C11: 5 | D11: qwen3.5:9b | E11: low | F11: =SUMIFS(Table1[Survival],Table1[Lineage],"="&Table15[[#This Row],[Lineage]],Table1[Gen],"="&Table15[[#This Row],[Gen]])/COUNTIFS(Table1[Lineage],"="&Table15[[#This Row],[Lineage]],Table1[Gen],"="&Table15[[#This Row],[Gen]]) -> 56457 | G11: normal | H11: =IFERROR(VALUE(VLOOKUP(Table15[[#This Row],[ID]],Skills!A:D,4,FALSE)),0) -> 0 | I11: TRUE | L11: =VLOOKUP(M11,B:D,3,FALSE) -> qwen3.5:9b | M11: 7 | N11: 83.448333 | O11: 62.239333 | P11: 72.117 | Q11: 84.421667 | R11: 70.463667
A12: =Table15[[#This Row],[Lineage]]&"-"&Table15[[#This Row],[Gen]] -> 3-1 | B12: 3 | C12: 1 | D12: qwen3.5:4b | E12: low | F12: =SUMIFS(Table1[Survival],Table1[Lineage],"="&Table15[[#This Row],[Lineage]],Table1[Gen],"="&Table15[[#This Row],[Gen]])/COUNTIFS(Table1[Lineage],"="&Table15[[#This Row],[Lineage]],Table1[Gen],"="&Table15[[#This Row],[Gen]]) -> 57431 | G12: normal | H12: =IFERROR(VALUE(VLOOKUP(Table15[[#This Row],[ID]],Skills!A:D,4,FALSE)),0) -> 0 | I12: TRUE | L12: =VLOOKUP(M12,B:D,3,FALSE) -> qwen3.5:9b | M12: 8 | N12: 70.073667 | O12: 69.770667 | P12: 79.835 | Q12: 84.599333 | R12: 74.357667
A13: =Table15[[#This Row],[Lineage]]&"-"&Table15[[#This Row],[Gen]] -> 3-2 | B13: 3 | C13: 2 | D13: qwen3.5:4b | E13: low | F13: =SUMIFS(Table1[Survival],Table1[Lineage],"="&Table15[[#This Row],[Lineage]],Table1[Gen],"="&Table15[[#This Row],[Gen]])/COUNTIFS(Table1[Lineage],"="&Table15[[#This Row],[Lineage]],Table1[Gen],"="&Table15[[#This Row],[Gen]]) -> 52184 | G13: normal | H13: =IFERROR(VALUE(VLOOKUP(Table15[[#This Row],[ID]],Skills!A:D,4,FALSE)),0) -> 0 | I13: TRUE | L13: =VLOOKUP(M13,B:D,3,FALSE) -> qwen3.5:9b | M13: 9 | N13: 78.373 | O13: 72.188 | P13: 54.6075 | Q13: 52.4195 | R13: 45.8365 | S13: 52.9695 | T13: 50.5955 | U13: 51.8585 | V13: 54.5865 | W13: 66.89 | X13: 49.915 | Y13: 72.6775 | Z13: 48.7565 | AA13: 54.3395 | AB13: 70.49 | AC13: 51.001 | AD13: 72.5715 | AE13: 70.9565 | AF13: 49.501 | AG13: 71.868
A14: =Table15[[#This Row],[Lineage]]&"-"&Table15[[#This Row],[Gen]] -> 3-3 | B14: 3 | C14: 3 | D14: qwen3.5:4b | E14: low | F14: =SUMIFS(Table1[Survival],Table1[Lineage],"="&Table15[[#This Row],[Lineage]],Table1[Gen],"="&Table15[[#This Row],[Gen]])/COUNTIFS(Table1[Lineage],"="&Table15[[#This Row],[Lineage]],Table1[Gen],"="&Table15[[#This Row],[Gen]]) -> 126108 | G14: normal | H14: =IFERROR(VALUE(VLOOKUP(Table15[[#This Row],[ID]],Skills!A:D,4,FALSE)),0) -> 1 | I14: TRUE | L14: =VLOOKUP(M14,B:D,3,FALSE) -> qwen3.5:9b | M14: 10 | N14: 69.478 | O14: 133.7515 | P14: 89.5735 | Q14: 119.1575 | R14: 122.113 | S14: 133.059 | T14: 83.44 | U14: 91.129 | V14: 74.9345 | W14: 91.6025 | X14: 115.7485 | Y14: 107.4375 | Z14: 93.359 | AA14: 85.481 | AB14: 79.6335 | AC14: 85.715 | AD14: 82.7075 | AE14: 96.8935 | AF14: 74.881 | AG14: 69.0555
A15: =Table15[[#This Row],[Lineage]]&"-"&Table15[[#This Row],[Gen]] -> 3-4 | B15: 3 | C15: 4 | D15: qwen3.5:4b | E15: low | F15: =SUMIFS(Table1[Survival],Table1[Lineage],"="&Table15[[#This Row],[Lineage]],Table1[Gen],"="&Table15[[#This Row],[Gen]])/COUNTIFS(Table1[Lineage],"="&Table15[[#This Row],[Lineage]],Table1[Gen],"="&Table15[[#This Row],[Gen]]) -> 79369 | G15: normal | H15: =IFERROR(VALUE(VLOOKUP(Table15[[#This Row],[ID]],Skills!A:D,4,FALSE)),0) -> 0 | I15: TRUE | L15: =VLOOKUP(M15,B:D,3,FALSE) -> qwen3.5:4b | M15: 11 | N15: 110.138 | O15: 62.4495 | P15: 76.0965 | Q15: 104.081 | R15: 53.2115
A16: =Table15[[#This Row],[Lineage]]&"-"&Table15[[#This Row],[Gen]] -> 3-5 | B16: 3 | C16: 5 | D16: qwen3.5:4b | E16: low | F16: =SUMIFS(Table1[Survival],Table1[Lineage],"="&Table15[[#This Row],[Lineage]],Table1[Gen],"="&Table15[[#This Row],[Gen]])/COUNTIFS(Table1[Lineage],"="&Table15[[#This Row],[Lineage]],Table1[Gen],"="&Table15[[#This Row],[Gen]]) -> 102443.5 | G16: normal | H16: =IFERROR(VALUE(VLOOKUP(Table15[[#This Row],[ID]],Skills!A:D,4,FALSE)),0) -> 0 | I16: TRUE | L16: =VLOOKUP(M16,B:D,3,FALSE) -> qwen3.5:9b | M16: 12 | N16: 115.57 | O16: 86.8 | P16: 43.2495 | Q16: 60.025 | R16: 71.244
A17: =Table15[[#This Row],[Lineage]]&"-"&Table15[[#This Row],[Gen]] -> 4-1 | B17: 4 | C17: 1 | D17: qwen3.5:9b | E17: low | F17: =SUMIFS(Table1[Survival],Table1[Lineage],"="&Table15[[#This Row],[Lineage]],Table1[Gen],"="&Table15[[#This Row],[Gen]])/COUNTIFS(Table1[Lineage],"="&Table15[[#This Row],[Lineage]],Table1[Gen],"="&Table15[[#This Row],[Gen]]) -> 61046.5 | G17: normal | H17: =IFERROR(VALUE(VLOOKUP(Table15[[#This Row],[ID]],Skills!A:D,4,FALSE)),0) -> 0 | I17: TRUE | L17: =VLOOKUP(M17,B:D,3,FALSE) -> qwen3.5:9b | M17: 13 | N17: 46.227 | O17: 50.621 | P17: 43.706 | Q17: 2.098 | R17: 2.112
A18: =Table15[[#This Row],[Lineage]]&"-"&Table15[[#This Row],[Gen]] -> 4-2 | B18: 4 | C18: 2 | D18: qwen3.5:9b | E18: low | F18: =SUMIFS(Table1[Survival],Table1[Lineage],"="&Table15[[#This Row],[Lineage]],Table1[Gen],"="&Table15[[#This Row],[Gen]])/COUNTIFS(Table1[Lineage],"="&Table15[[#This Row],[Lineage]],Table1[Gen],"="&Table15[[#This Row],[Gen]]) -> 104193.5 | G18: normal | H18: =IFERROR(VALUE(VLOOKUP(Table15[[#This Row],[ID]],Skills!A:D,4,FALSE)),0) -> 1 | I18: TRUE | L18: =VLOOKUP(M18,B:D,3,FALSE) -> qwen3.5:4b | M18: 14 | N18: 85.703 | O18: 49.5685 | P18: 52.825 | Q18: 57.3585 | R18: 56.951 | S18: 48.6375 | T18: 56.5135 | U18: 53.744 | V18: 68.3635 | W18: 68.7415 | X18: 71.373 | Y18: 53.4545 | Z18: 57.2225 | AA18: 50.171 | AB18: 57.176 | AC18: 56.1735 | AD18: 55.893 | AE18: 59.845 | AF18: 55.307 | AG18: 70.123
A19: =Table15[[#This Row],[Lineage]]&"-"&Table15[[#This Row],[Gen]] -> 4-3 | B19: 4 | C19: 3 | D19: qwen3.5:9b | E19: low | F19: =SUMIFS(Table1[Survival],Table1[Lineage],"="&Table15[[#This Row],[Lineage]],Table1[Gen],"="&Table15[[#This Row],[Gen]])/COUNTIFS(Table1[Lineage],"="&Table15[[#This Row],[Lineage]],Table1[Gen],"="&Table15[[#This Row],[Gen]]) -> 83307 | G19: normal | H19: =IFERROR(VALUE(VLOOKUP(Table15[[#This Row],[ID]],Skills!A:D,4,FALSE)),0) -> 0 | I19: TRUE | L19: =VLOOKUP(M19,B:D,3,FALSE) -> qwen3.5:4b | M19: 15 | N19: 129.5265 | O19: 129.414 | P19: 103.476 | Q19: 103.4105 | R19: 65.0995 | S19: 89.4905 | T19: 77.1205 | U19: 129.4835 | V19: 102.6645 | W19: 98.215 | X19: 82.7 | Y19: 99.5965 | Z19: 79.0205 | AA19: 103.375
A20: =Table15[[#This Row],[Lineage]]&"-"&Table15[[#This Row],[Gen]] -> 4-4 | B20: 4 | C20: 4 | D20: qwen3.5:9b | E20: low | F20: =SUMIFS(Table1[Survival],Table1[Lineage],"="&Table15[[#This Row],[Lineage]],Table1[Gen],"="&Table15[[#This Row],[Gen]])/COUNTIFS(Table1[Lineage],"="&Table15[[#This Row],[Lineage]],Table1[Gen],"="&Table15[[#This Row],[Gen]]) -> 116711.5 | G20: normal | H20: =IFERROR(VALUE(VLOOKUP(Table15[[#This Row],[ID]],Skills!A:D,4,FALSE)),0) -> 0 | I20: TRUE | L20: =VLOOKUP(M20,B:D,3,FALSE) -> x-ai/grok-4.1-fast | M20: 16 | N20: 131.055 | O20: 128.001 | P20: 126.3965 | Q20: 130.6445 | R20: 130.9955
A21: =Table15[[#This Row],[Lineage]]&"-"&Table15[[#This Row],[Gen]] -> 4-5 | B21: 4 | C21: 5 | D21: qwen3.5:9b | E21: low | F21: =SUMIFS(Table1[Survival],Table1[Lineage],"="&Table15[[#This Row],[Lineage]],Table1[Gen],"="&Table15[[#This Row],[Gen]])/COUNTIFS(Table1[Lineage],"="&Table15[[#This Row],[Lineage]],Table1[Gen],"="&Table15[[#This Row],[Gen]]) -> 76426.5 | G21: normal | H21: =IFERROR(VALUE(VLOOKUP(Table15[[#This Row],[ID]],Skills!A:D,4,FALSE)),0) -> 0 | I21: TRUE | L21: =VLOOKUP(M21,B:D,3,FALSE) -> qwen3.5:4b | M21: 17 | N21: 125.929 | O21: 73.5185 | P21: 87.2465 | Q21: 69.2025 | R21: 85.5695 | S21: 79.1555 | T21: 85.059 | U21: 70.31 | V21: 68.8205 | W21: 74.9235 | X21: 97.704 | Y21: 93.81 | Z21: 74.9695 | AA21: 77.106 | AB21: 130.171 | AC21: 87.3145 | AD21: 99.207 | AE21: 100.528 | AF21: 100.9975 | AG21: 88.3985
A22: =Table15[[#This Row],[Lineage]]&"-"&Table15[[#This Row],[Gen]] -> 5-1 | B22: 5 | C22: 1 | D22: qwen3.5:4b | E22: low | F22: =SUMIFS(Table1[Survival],Table1[Lineage],"="&Table15[[#This Row],[Lineage]],Table1[Gen],"="&Table15[[#This Row],[Gen]])/COUNTIFS(Table1[Lineage],"="&Table15[[#This Row],[Lineage]],Table1[Gen],"="&Table15[[#This Row],[Gen]]) -> 104140 | G22: normal | H22: =IFERROR(VALUE(VLOOKUP(Table15[[#This Row],[ID]],Skills!A:D,4,FALSE)),0) -> 0 | I22: TRUE | L22: =VLOOKUP(M22,B:D,3,FALSE) -> moonshotai/kimi-k2.6 | M22: 18 | N22: 111.965 | O22: 102.167 | P22: 109.644 | Q22: 145.173 | R22: 116.147
A23: =Table15[[#This Row],[Lineage]]&"-"&Table15[[#This Row],[Gen]] -> 5-2 | B23: 5 | C23: 2 | D23: qwen3.5:4b | E23: low | F23: =SUMIFS(Table1[Survival],Table1[Lineage],"="&Table15[[#This Row],[Lineage]],Table1[Gen],"="&Table15[[#This Row],[Gen]])/COUNTIFS(Table1[Lineage],"="&Table15[[#This Row],[Lineage]],Table1[Gen],"="&Table15[[#This Row],[Gen]]) -> 78553.5 | G23: normal | H23: =IFERROR(VALUE(VLOOKUP(Table15[[#This Row],[ID]],Skills!A:D,4,FALSE)),0) -> 0 | I23: TRUE | L23: =VLOOKUP(M23,B:D,3,FALSE) -> qwen3.5:9b | M23: 19 | N23: 104.152 | O23: 100.1485 | P23: 129.4825 | Q23: 91.961 | R23: 85.231
A24: =Table15[[#This Row],[Lineage]]&"-"&Table15[[#This Row],[Gen]] -> 5-3 | B24: 5 | C24: 3 | D24: qwen3.5:4b | E24: low | F24: =SUMIFS(Table1[Survival],Table1[Lineage],"="&Table15[[#This Row],[Lineage]],Table1[Gen],"="&Table15[[#This Row],[Gen]])/COUNTIFS(Table1[Lineage],"="&Table15[[#This Row],[Lineage]],Table1[Gen],"="&Table15[[#This Row],[Gen]]) -> 116326 | G24: normal | H24: =IFERROR(VALUE(VLOOKUP(Table15[[#This Row],[ID]],Skills!A:D,4,FALSE)),0) -> 0 | I24: TRUE | L24: =VLOOKUP(M24,B:D,3,FALSE) -> qwen3.5:9b | M24: 20 | N24: 58.8035 | O24: 76.725 | P24: 72.0865 | Q24: 66.7505 | R24: 56.5245
A25: =Table15[[#This Row],[Lineage]]&"-"&Table15[[#This Row],[Gen]] -> 5-4 | B25: 5 | C25: 4 | D25: qwen3.5:4b | E25: low | F25: =SUMIFS(Table1[Survival],Table1[Lineage],"="&Table15[[#This Row],[Lineage]],Table1[Gen],"="&Table15[[#This Row],[Gen]])/COUNTIFS(Table1[Lineage],"="&Table15[[#This Row],[Lineage]],Table1[Gen],"="&Table15[[#This Row],[Gen]]) -> 110546 | G25: normal | H25: =IFERROR(VALUE(VLOOKUP(Table15[[#This Row],[ID]],Skills!A:D,4,FALSE)),0) -> 0 | I25: TRUE | L25: =VLOOKUP(M25,B:D,3,FALSE) -> qwen3.5:9b | M25: 21 | N25: 53.6175 | O25: 50.859 | P25: 126.152 | Q25: 90.3585 | R25: 70.136
A26: =Table15[[#This Row],[Lineage]]&"-"&Table15[[#This Row],[Gen]] -> 5-5 | B26: 5 | C26: 5 | D26: qwen3.5:4b | E26: low | F26: =SUMIFS(Table1[Survival],Table1[Lineage],"="&Table15[[#This Row],[Lineage]],Table1[Gen],"="&Table15[[#This Row],[Gen]])/COUNTIFS(Table1[Lineage],"="&Table15[[#This Row],[Lineage]],Table1[Gen],"="&Table15[[#This Row],[Gen]]) -> 73580 | G26: normal | H26: =IFERROR(VALUE(VLOOKUP(Table15[[#This Row],[ID]],Skills!A:D,4,FALSE)),0) -> 0 | I26: TRUE | L26: =VLOOKUP(M26,B:D,3,FALSE) -> qwen3.5:9b | M26: 22 | N26: 50.0175 | O26: 85.247 | P26: 99.954 | Q26: 46.556 | R26: 86.936 | S26: 80.388 | T26: 213.824 | U26: 55.179 | V26: 85.3095
A27: =Table15[[#This Row],[Lineage]]&"-"&Table15[[#This Row],[Gen]] -> 5-6 | B27: 5 | C27: 6 | D27: qwen3.5:4b | E27: low | F27: =SUMIFS(Table1[Survival],Table1[Lineage],"="&Table15[[#This Row],[Lineage]],Table1[Gen],"="&Table15[[#This Row],[Gen]])/COUNTIFS(Table1[Lineage],"="&Table15[[#This Row],[Lineage]],Table1[Gen],"="&Table15[[#This Row],[Gen]]) -> 73292.5 | G27: normal | H27: =IFERROR(VALUE(VLOOKUP(Table15[[#This Row],[ID]],Skills!A:D,4,FALSE)),0) -> 2 | I27: TRUE | L27: =VLOOKUP(M27,B:D,3,FALSE) -> openai/gpt-5.5 | M27: 23 | N27: 81.227 | O27: 64.1425 | P27: 75.2565 | Q27: 87.006
A28: =Table15[[#This Row],[Lineage]]&"-"&Table15[[#This Row],[Gen]] -> 5-7 | B28: 5 | C28: 7 | D28: qwen3.5:4b | E28: low | F28: =SUMIFS(Table1[Survival],Table1[Lineage],"="&Table15[[#This Row],[Lineage]],Table1[Gen],"="&Table15[[#This Row],[Gen]])/COUNTIFS(Table1[Lineage],"="&Table15[[#This Row],[Lineage]],Table1[Gen],"="&Table15[[#This Row],[Gen]]) -> 72772.5 | G28: normal | H28: =IFERROR(VALUE(VLOOKUP(Table15[[#This Row],[ID]],Skills!A:D,4,FALSE)),0) -> 0 | I28: TRUE
A29: =Table15[[#This Row],[Lineage]]&"-"&Table15[[#This Row],[Gen]] -> 5-8 | B29: 5 | C29: 8 | D29: qwen3.5:4b | E29: low | F29: =SUMIFS(Table1[Survival],Table1[Lineage],"="&Table15[[#This Row],[Lineage]],Table1[Gen],"="&Table15[[#This Row],[Gen]])/COUNTIFS(Table1[Lineage],"="&Table15[[#This Row],[Lineage]],Table1[Gen],"="&Table15[[#This Row],[Gen]]) -> 72222.5 | G29: normal | H29: =IFERROR(VALUE(VLOOKUP(Table15[[#This Row],[ID]],Skills!A:D,4,FALSE)),0) -> 0 | I29: TRUE
A30: =Table15[[#This Row],[Lineage]]&"-"&Table15[[#This Row],[Gen]] -> 5-9 | B30: 5 | C30: 9 | D30: qwen3.5:4b | E30: low | F30: =SUMIFS(Table1[Survival],Table1[Lineage],"="&Table15[[#This Row],[Lineage]],Table1[Gen],"="&Table15[[#This Row],[Gen]])/COUNTIFS(Table1[Lineage],"="&Table15[[#This Row],[Lineage]],Table1[Gen],"="&Table15[[#This Row],[Gen]]) -> 49914 | G30: normal | H30: =IFERROR(VALUE(VLOOKUP(Table15[[#This Row],[ID]],Skills!A:D,4,FALSE)),0) -> 0 | I30: TRUE
A31: =Table15[[#This Row],[Lineage]]&"-"&Table15[[#This Row],[Gen]] -> 5-10 | B31: 5 | C31: 10 | D31: qwen3.5:4b | E31: low | F31: =SUMIFS(Table1[Survival],Table1[Lineage],"="&Table15[[#This Row],[Lineage]],Table1[Gen],"="&Table15[[#This Row],[Gen]])/COUNTIFS(Table1[Lineage],"="&Table15[[#This Row],[Lineage]],Table1[Gen],"="&Table15[[#This Row],[Gen]]) -> 74210.5 | G31: normal | H31: =IFERROR(VALUE(VLOOKUP(Table15[[#This Row],[ID]],Skills!A:D,4,FALSE)),0) -> 0 | I31: TRUE
A32: =Table15[[#This Row],[Lineage]]&"-"&Table15[[#This Row],[Gen]] -> 6-1 | B32: 6 | C32: 1 | D32: qwen3.5:9b | E32: low | F32: =SUMIFS(Table1[Survival],Table1[Lineage],"="&Table15[[#This Row],[Lineage]],Table1[Gen],"="&Table15[[#This Row],[Gen]])/COUNTIFS(Table1[Lineage],"="&Table15[[#This Row],[Lineage]],Table1[Gen],"="&Table15[[#This Row],[Gen]]) -> 79465 | G32: normal | H32: =IFERROR(VALUE(VLOOKUP(Table15[[#This Row],[ID]],Skills!A:D,4,FALSE)),0) -> 0 | I32: TRUE
A33: =Table15[[#This Row],[Lineage]]&"-"&Table15[[#This Row],[Gen]] -> 6-2 | B33: 6 | C33: 2 | D33: qwen3.5:9b | E33: low | F33: =SUMIFS(Table1[Survival],Table1[Lineage],"="&Table15[[#This Row],[Lineage]],Table1[Gen],"="&Table15[[#This Row],[Gen]])/COUNTIFS(Table1[Lineage],"="&Table15[[#This Row],[Lineage]],Table1[Gen],"="&Table15[[#This Row],[Gen]]) -> 73288.5 | G33: normal | H33: =IFERROR(VALUE(VLOOKUP(Table15[[#This Row],[ID]],Skills!A:D,4,FALSE)),0) -> 0 | I33: TRUE
A34: =Table15[[#This Row],[Lineage]]&"-"&Table15[[#This Row],[Gen]] -> 6-3 | B34: 6 | C34: 3 | D34: qwen3.5:9b | E34: low | F34: =SUMIFS(Table1[Survival],Table1[Lineage],"="&Table15[[#This Row],[Lineage]],Table1[Gen],"="&Table15[[#This Row],[Gen]])/COUNTIFS(Table1[Lineage],"="&Table15[[#This Row],[Lineage]],Table1[Gen],"="&Table15[[#This Row],[Gen]]) -> 56894.5 | G34: normal | H34: =IFERROR(VALUE(VLOOKUP(Table15[[#This Row],[ID]],Skills!A:D,4,FALSE)),0) -> 0 | I34: TRUE
A35: =Table15[[#This Row],[Lineage]]&"-"&Table15[[#This Row],[Gen]] -> 6-4 | B35: 6 | C35: 4 | D35: qwen3.5:9b | E35: low | F35: =SUMIFS(Table1[Survival],Table1[Lineage],"="&Table15[[#This Row],[Lineage]],Table1[Gen],"="&Table15[[#This Row],[Gen]])/COUNTIFS(Table1[Lineage],"="&Table15[[#This Row],[Lineage]],Table1[Gen],"="&Table15[[#This Row],[Gen]]) -> 71935 | G35: normal | H35: =IFERROR(VALUE(VLOOKUP(Table15[[#This Row],[ID]],Skills!A:D,4,FALSE)),0) -> 1 | I35: TRUE
A36: =Table15[[#This Row],[Lineage]]&"-"&Table15[[#This Row],[Gen]] -> 6-5 | B36: 6 | C36: 5 | D36: qwen3.5:9b | E36: low | F36: =SUMIFS(Table1[Survival],Table1[Lineage],"="&Table15[[#This Row],[Lineage]],Table1[Gen],"="&Table15[[#This Row],[Gen]])/COUNTIFS(Table1[Lineage],"="&Table15[[#This Row],[Lineage]],Table1[Gen],"="&Table15[[#This Row],[Gen]]) -> 68376 | G36: normal | H36: =IFERROR(VALUE(VLOOKUP(Table15[[#This Row],[ID]],Skills!A:D,4,FALSE)),0) -> 0 | I36: TRUE
A37: =Table15[[#This Row],[Lineage]]&"-"&Table15[[#This Row],[Gen]] -> 6-6 | B37: 6 | C37: 6 | D37: qwen3.5:9b | E37: low | F37: =SUMIFS(Table1[Survival],Table1[Lineage],"="&Table15[[#This Row],[Lineage]],Table1[Gen],"="&Table15[[#This Row],[Gen]])/COUNTIFS(Table1[Lineage],"="&Table15[[#This Row],[Lineage]],Table1[Gen],"="&Table15[[#This Row],[Gen]]) -> 76427 | G37: normal | H37: =IFERROR(VALUE(VLOOKUP(Table15[[#This Row],[ID]],Skills!A:D,4,FALSE)),0) -> 0 | I37: TRUE
A38: =Table15[[#This Row],[Lineage]]&"-"&Table15[[#This Row],[Gen]] -> 6-7 | B38: 6 | C38: 7 | D38: qwen3.5:9b | E38: low | F38: =SUMIFS(Table1[Survival],Table1[Lineage],"="&Table15[[#This Row],[Lineage]],Table1[Gen],"="&Table15[[#This Row],[Gen]])/COUNTIFS(Table1[Lineage],"="&Table15[[#This Row],[Lineage]],Table1[Gen],"="&Table15[[#This Row],[Gen]]) -> 79428.5 | G38: normal | H38: =IFERROR(VALUE(VLOOKUP(Table15[[#This Row],[ID]],Skills!A:D,4,FALSE)),0) -> 0 | I38: TRUE
A39: =Table15[[#This Row],[Lineage]]&"-"&Table15[[#This Row],[Gen]] -> 6-8 | B39: 6 | C39: 8 | D39: qwen3.5:9b | E39: low | F39: =SUMIFS(Table1[Survival],Table1[Lineage],"="&Table15[[#This Row],[Lineage]],Table1[Gen],"="&Table15[[#This Row],[Gen]])/COUNTIFS(Table1[Lineage],"="&Table15[[#This Row],[Lineage]],Table1[Gen],"="&Table15[[#This Row],[Gen]]) -> 54023.5 | G39: normal | H39: =IFERROR(VALUE(VLOOKUP(Table15[[#This Row],[ID]],Skills!A:D,4,FALSE)),0) -> 0 | I39: TRUE
... A196: =Table15[[#This Row],[Lineage]]&"-"&Table15[[#This Row],[Gen]] -> 23-4 | B196: 23 | C196: 4 | D196: openai/gpt-5.5 | E196: low | F196: =SUMIFS(Table1[Survival],Table1[Lineage],"="&Table15[[#This Row],[Lineage]],Table1[Gen],"="&Table15[[#This Row],[Gen]])/COUNTIFS(Table1[Lineage],"="&Table15[[#This Row],[Lineage]],Table1[Gen],"="&Table15[[#This Row],[Gen]]) -> 87006 | G196: Real Run 13 - State of the art | H196: =IFERROR(VALUE(VLOOKUP(Table15[[#This Row],[ID]],Skills!A:D,4,FALSE)),0) -> 1 | I196: FALSE

Sheet 4b vs 9b
A1: Generation | B1: qwen3.5:4b average survival time (s) | C1: qwen3.5:4b average survival time std | D1: qwen3.5:9b average survival time (s) | E1: qwen3.5:9b average survival time std
A2: 1 | B2: =AVERAGEIFS(Table15[Survival],Table15[Model],"=qwen3.5:4b",Table15[Gen],"="&Table7[[#This Row],[Generation]])/1000 -> 100.36836 | C2: {=_xlfn.STDEV.S(_xlfn._xlws.FILTER(Table15[Survival],(Table15[Model]="qwen3.5:4b")*(Table15[Gen]=Table7[[#This Row],[Generation]])))/1000} -> 25.118 | D2: =AVERAGEIFS(Table15[Survival],Table15[Model],"=qwen3.5:9b",Table15[Gen],"="&Table7[[#This Row],[Generation]])/1000 -> 72.099769 | E2: {=_xlfn.STDEV.S(_xlfn._xlws.FILTER(Table15[Survival],(Table15[Model]="qwen3.5:9b")*(Table15[Gen]=Table7[[#This Row],[Generation]])))/1000} -> 20.35869
A3: 2 | B3: =AVERAGEIFS(Table15[Survival],Table15[Model],"=qwen3.5:4b",Table15[Gen],"="&Table7[[#This Row],[Generation]])/1000 -> 77.418357 | C3: {=_xlfn.STDEV.S(_xlfn._xlws.FILTER(Table15[Survival],(Table15[Model]="qwen3.5:4b")*(Table15[Gen]=Table7[[#This Row],[Generation]])))/1000} -> 28.020146 | D3: =AVERAGEIFS(Table15[Survival],Table15[Model],"=qwen3.5:9b",Table15[Gen],"="&Table7[[#This Row],[Generation]])/1000 -> 78.624077 | E3: {=_xlfn.STDEV.S(_xlfn._xlws.FILTER(Table15[Survival],(Table15[Model]="qwen3.5:9b")*(Table15[Gen]=Table7[[#This Row],[Generation]])))/1000} -> 23.70208
A4: 3 | B4: =AVERAGEIFS(Table15[Survival],Table15[Model],"=qwen3.5:4b",Table15[Gen],"="&Table7[[#This Row],[Generation]])/1000 -> 94.795786 | C4: {=_xlfn.STDEV.S(_xlfn._xlws.FILTER(Table15[Survival],(Table15[Model]="qwen3.5:4b")*(Table15[Gen]=Table7[[#This Row],[Generation]])))/1000} -> 24.94126 | D4: =AVERAGEIFS(Table15[Survival],Table15[Model],"=qwen3.5:9b",Table15[Gen],"="&Table7[[#This Row],[Generation]])/1000 -> 78.415346 | E4: {=_xlfn.STDEV.S(_xlfn._xlws.FILTER(Table15[Survival],(Table15[Model]="qwen3.5:9b")*(Table15[Gen]=Table7[[#This Row],[Generation]])))/1000} -> 27.615938
A5: 4 | B5: =AVERAGEIFS(Table15[Survival],Table15[Model],"=qwen3.5:4b",Table15[Gen],"="&Table7[[#This Row],[Generation]])/1000 -> 90.268286 | C5: {=_xlfn.STDEV.S(_xlfn._xlws.FILTER(Table15[Survival],(Table15[Model]="qwen3.5:4b")*(Table15[Gen]=Table7[[#This Row],[Generation]])))/1000} -> 21.336815 | D5: =AVERAGEIFS(Table15[Survival],Table15[Model],"=qwen3.5:9b",Table15[Gen],"="&Table7[[#This Row],[Generation]])/1000 -> 79.381917 | E5: {=_xlfn.STDEV.S(_xlfn._xlws.FILTER(Table15[Survival],(Table15[Model]="qwen3.5:9b")*(Table15[Gen]=Table7[[#This Row],[Generation]])))/1000} -> 23.037333
A6: 5 | B6: =AVERAGEIFS(Table15[Survival],Table15[Model],"=qwen3.5:4b",Table15[Gen],"="&Table7[[#This Row],[Generation]])/1000 -> 74.977214 | C6: {=_xlfn.STDEV.S(_xlfn._xlws.FILTER(Table15[Survival],(Table15[Model]="qwen3.5:4b")*(Table15[Gen]=Table7[[#This Row],[Generation]])))/1000} -> 17.953742 | D6: =AVERAGEIFS(Table15[Survival],Table15[Model],"=qwen3.5:9b",Table15[Gen],"="&Table7[[#This Row],[Generation]])/1000 -> 73.675153 | E6: {=_xlfn.STDEV.S(_xlfn._xlws.FILTER(Table15[Survival],(Table15[Model]="qwen3.5:9b")*(Table15[Gen]=Table7[[#This Row],[Generation]])))/1000} -> 19.273344
A7: 6 | B7: =AVERAGEIFS(Table15[Survival],Table15[Model],"=qwen3.5:4b",Table15[Gen],"="&Table7[[#This Row],[Generation]])/1000 -> 72.644 | C7: {=_xlfn.STDEV.S(_xlfn._xlws.FILTER(Table15[Survival],(Table15[Model]="qwen3.5:4b")*(Table15[Gen]=Table7[[#This Row],[Generation]])))/1000} -> 17.348744 | D7: =AVERAGEIFS(Table15[Survival],Table15[Model],"=qwen3.5:9b",Table15[Gen],"="&Table7[[#This Row],[Generation]])/1000 -> 85.710875 | E7: {=_xlfn.STDEV.S(_xlfn._xlws.FILTER(Table15[Survival],(Table15[Model]="qwen3.5:9b")*(Table15[Gen]=Table7[[#This Row],[Generation]])))/1000} -> 33.805157
A8: 7 | B8: =AVERAGEIFS(Table15[Survival],Table15[Model],"=qwen3.5:4b",Table15[Gen],"="&Table7[[#This Row],[Generation]])/1000 -> 72.866375 | C8: {=_xlfn.STDEV.S(_xlfn._xlws.FILTER(Table15[Survival],(Table15[Model]="qwen3.5:4b")*(Table15[Gen]=Table7[[#This Row],[Generation]])))/1000} -> 12.030281 | D8: =AVERAGEIFS(Table15[Survival],Table15[Model],"=qwen3.5:9b",Table15[Gen],"="&Table7[[#This Row],[Generation]])/1000 -> 78.63825 | E8: {=_xlfn.STDEV.S(_xlfn._xlws.FILTER(Table15[Survival],(Table15[Model]="qwen3.5:9b")*(Table15[Gen]=Table7[[#This Row],[Generation]])))/1000} -> 20.929352
A9: 8 | B9: =AVERAGEIFS(Table15[Survival],Table15[Model],"=qwen3.5:4b",Table15[Gen],"="&Table7[[#This Row],[Generation]])/1000 -> 81.44 | C9: {=_xlfn.STDEV.S(_xlfn._xlws.FILTER(Table15[Survival],(Table15[Model]="qwen3.5:4b")*(Table15[Gen]=Table7[[#This Row],[Generation]])))/1000} -> 33.086178 | D9: =AVERAGEIFS(Table15[Survival],Table15[Model],"=qwen3.5:9b",Table15[Gen],"="&Table7[[#This Row],[Generation]])/1000 -> 63.0475 | E9: {=_xlfn.STDEV.S(_xlfn._xlws.FILTER(Table15[Survival],(Table15[Model]="qwen3.5:9b")*(Table15[Gen]=Table7[[#This Row],[Generation]])))/1000} -> 18.771523
A10: 9 | B10: =AVERAGEIFS(Table15[Survival],Table15[Model],"=qwen3.5:4b",Table15[Gen],"="&Table7[[#This Row],[Generation]])/1000 -> 72.440625 | C10: {=_xlfn.STDEV.S(_xlfn._xlws.FILTER(Table15[Survival],(Table15[Model]="qwen3.5:4b")*(Table15[Gen]=Table7[[#This Row],[Generation]])))/1000} -> 21.989844 | D10: =AVERAGEIFS(Table15[Survival],Table15[Model],"=qwen3.5:9b",Table15[Gen],"="&Table7[[#This Row],[Generation]])/1000 -> 81.424375 | E10: {=_xlfn.STDEV.S(_xlfn._xlws.FILTER(Table15[Survival],(Table15[Model]="qwen3.5:9b")*(Table15[Gen]=Table7[[#This Row],[Generation]])))/1000} -> 24.40751
A11: 10 | B11: =AVERAGEIFS(Table15[Survival],Table15[Model],"=qwen3.5:4b",Table15[Gen],"="&Table7[[#This Row],[Generation]])/1000 -> 79.022625 | C11: {=_xlfn.STDEV.S(_xlfn._xlws.FILTER(Table15[Survival],(Table15[Model]="qwen3.5:4b")*(Table15[Gen]=Table7[[#This Row],[Generation]])))/1000} -> 13.08954 | D11: =AVERAGEIFS(Table15[Survival],Table15[Model],"=qwen3.5:9b",Table15[Gen],"="&Table7[[#This Row],[Generation]])/1000 -> 80.745167 | E11: {=_xlfn.STDEV.S(_xlfn._xlws.FILTER(Table15[Survival],(Table15[Model]="qwen3.5:9b")*(Table15[Gen]=Table7[[#This Row],[Generation]])))/1000} -> 12.626051
A12: 11 | B12: =AVERAGEIFS(Table15[Survival],Table15[Model],"=qwen3.5:4b",Table15[Gen],"="&Table7[[#This Row],[Generation]])/1000 -> 83.925667 | C12: {=_xlfn.STDEV.S(_xlfn._xlws.FILTER(Table15[Survival],(Table15[Model]="qwen3.5:4b")*(Table15[Gen]=Table7[[#This Row],[Generation]])))/1000} -> 13.20822 | D12: =AVERAGEIFS(Table15[Survival],Table15[Model],"=qwen3.5:9b",Table15[Gen],"="&Table7[[#This Row],[Generation]])/1000 -> 82.83175 | E12: {=_xlfn.STDEV.S(_xlfn._xlws.FILTER(Table15[Survival],(Table15[Model]="qwen3.5:9b")*(Table15[Gen]=Table7[[#This Row],[Generation]])))/1000} -> 46.551314
A13: 12 | B13: =AVERAGEIFS(Table15[Survival],Table15[Model],"=qwen3.5:4b",Table15[Gen],"="&Table7[[#This Row],[Generation]])/1000 -> 82.287 | C13: {=_xlfn.STDEV.S(_xlfn._xlws.FILTER(Table15[Survival],(Table15[Model]="qwen3.5:4b")*(Table15[Gen]=Table7[[#This Row],[Generation]])))/1000} -> 25.13674 | D13: =AVERAGEIFS(Table15[Survival],Table15[Model],"=qwen3.5:9b",Table15[Gen],"="&Table7[[#This Row],[Generation]])/1000 -> 90.0575 | E13: {=_xlfn.STDEV.S(_xlfn._xlws.FILTER(Table15[Survival],(Table15[Model]="qwen3.5:9b")*(Table15[Gen]=Table7[[#This Row],[Generation]])))/1000} -> 24.579032
... A21: 20 | B21: =AVERAGEIFS(Table15[Survival],Table15[Model],"=qwen3.5:4b",Table15[Gen],"="&Table7[[#This Row],[Generation]])/1000 -> 79.26075 | C21: {=_xlfn.STDEV.S(_xlfn._xlws.FILTER(Table15[Survival],(Table15[Model]="qwen3.5:4b")*(Table15[Gen]=Table7[[#This Row],[Generation]])))/1000} -> 12.92273 | D21: =AVERAGEIFS(Table15[Survival],Table15[Model],"=qwen3.5:9b",Table15[Gen],"="&Table7[[#This Row],[Generation]])/1000 -> 70.46175 | E21: {=_xlfn.STDEV.S(_xlfn._xlws.FILTER(Table15[Survival],(Table15[Model]="qwen3.5:9b")*(Table15[Gen]=Table7[[#This Row],[Generation]])))/1000} -> 1.9887378
A25: Generation | B25: Tools average survival time (s) | C25: Tools average survival time std | D25: No tools average survival time (s) | E25: No tools average survival time std
A26: 1 | B26: =AVERAGEIFS(Table15[Survival],Table15[StartingSkills],TRUE,Table15[Gen],"="&Table74[[#This Row],[Generation]])/1000 -> 93.246029 | C26: {=_xlfn.STDEV.S(_xlfn._xlws.FILTER(Table15[Survival],(Table15[StartingSkills]=TRUE)*(Table15[Gen]=Table74[[#This Row],[Generation]])))/1000} -> 25.336861 | D26: =AVERAGEIFS(Table15[Survival],Table15[StartingSkills],FALSE,Table15[Gen],"="&Table74[[#This Row],[Generation]])/1000 -> 63.156667 | E26: {=_xlfn.STDEV.S(_xlfn._xlws.FILTER(Table15[Survival],(Table15[StartingSkills]=FALSE)*(Table15[Gen]=Table74[[#This Row],[Generation]])))/1000} -> 15.154405
A27: 2 | B27: =AVERAGEIFS(Table15[Survival],Table15[StartingSkills],TRUE,Table15[Gen],"="&Table74[[#This Row],[Generation]])/1000 -> 82.443706 | C27: {=_xlfn.STDEV.S(_xlfn._xlws.FILTER(Table15[Survival],(Table15[StartingSkills]=TRUE)*(Table15[Gen]=Table74[[#This Row],[Generation]])))/1000} -> 24.402033 | D27: =AVERAGEIFS(Table15[Survival],Table15[StartingSkills],FALSE,Table15[Gen],"="&Table74[[#This Row],[Generation]])/1000 -> 76.134833 | E27: {=_xlfn.STDEV.S(_xlfn._xlws.FILTER(Table15[Survival],(Table15[StartingSkills]=FALSE)*(Table15[Gen]=Table74[[#This Row],[Generation]])))/1000} -> 31.151016
A28: 3 | B28: =AVERAGEIFS(Table15[Survival],Table15[StartingSkills],TRUE,Table15[Gen],"="&Table74[[#This Row],[Generation]])/1000 -> 88.530441 | C28: {=_xlfn.STDEV.S(_xlfn._xlws.FILTER(Table15[Survival],(Table15[StartingSkills]=TRUE)*(Table15[Gen]=Table74[[#This Row],[Generation]])))/1000} -> 26.99724 | D28: =AVERAGEIFS(Table15[Survival],Table15[StartingSkills],FALSE,Table15[Gen],"="&Table74[[#This Row],[Generation]])/1000 -> 81.541583 | E28: {=_xlfn.STDEV.S(_xlfn._xlws.FILTER(Table15[Survival],(Table15[StartingSkills]=FALSE)*(Table15[Gen]=Table74[[#This Row],[Generation]])))/1000} -> 30.298833
A29: 4 | B29: =AVERAGEIFS(Table15[Survival],Table15[StartingSkills],TRUE,Table15[Gen],"="&Table74[[#This Row],[Generation]])/1000 -> 91.281588 | C29: {=_xlfn.STDEV.S(_xlfn._xlws.FILTER(Table15[Survival],(Table15[StartingSkills]=TRUE)*(Table15[Gen]=Table74[[#This Row],[Generation]])))/1000} -> 25.545354 | D29: =AVERAGEIFS(Table15[Survival],Table15[StartingSkills],FALSE,Table15[Gen],"="&Table74[[#This Row],[Generation]])/1000 -> 79.0995 | E29: {=_xlfn.STDEV.S(_xlfn._xlws.FILTER(Table15[Survival],(Table15[StartingSkills]=FALSE)*(Table15[Gen]=Table74[[#This Row],[Generation]])))/1000} -> 29.853069
A30: 5 | B30: =AVERAGEIFS(Table15[Survival],Table15[StartingSkills],TRUE,Table15[Gen],"="&Table74[[#This Row],[Generation]])/1000 -> 78.297843 | C30: {=_xlfn.STDEV.S(_xlfn._xlws.FILTER(Table15[Survival],(Table15[StartingSkills]=TRUE)*(Table15[Gen]=Table74[[#This Row],[Generation]])))/1000} -> 21.576288 | D30: =AVERAGEIFS(Table15[Survival],Table15[StartingSkills],FALSE,Table15[Gen],"="&Table74[[#This Row],[Generation]])/1000 -> 81.255375 | E30: {=_xlfn.STDEV.S(_xlfn._xlws.FILTER(Table15[Survival],(Table15[StartingSkills]=FALSE)*(Table15[Gen]=Table74[[#This Row],[Generation]])))/1000} -> 32.040351
A31: 6 | B31: =AVERAGEIFS(Table15[Survival],Table15[StartingSkills],TRUE,Table15[Gen],"="&Table74[[#This Row],[Generation]])/1000 -> 73.4006 | C31: {=_xlfn.STDEV.S(_xlfn._xlws.FILTER(Table15[Survival],(Table15[StartingSkills]=TRUE)*(Table15[Gen]=Table74[[#This Row],[Generation]])))/1000} -> 15.119405 | D31: =AVERAGEIFS(Table15[Survival],Table15[StartingSkills],FALSE,Table15[Gen],"="&Table74[[#This Row],[Generation]])/1000 -> 88.8055 | E31: {=_xlfn.STDEV.S(_xlfn._xlws.FILTER(Table15[Survival],(Table15[StartingSkills]=FALSE)*(Table15[Gen]=Table74[[#This Row],[Generation]])))/1000} -> 40.702859
A32: 7 | B32: =AVERAGEIFS(Table15[Survival],Table15[StartingSkills],TRUE,Table15[Gen],"="&Table74[[#This Row],[Generation]])/1000 -> 74.1788 | C32: {=_xlfn.STDEV.S(_xlfn._xlws.FILTER(Table15[Survival],(Table15[StartingSkills]=TRUE)*(Table15[Gen]=Table74[[#This Row],[Generation]])))/1000} -> 10.823957 | D32: =AVERAGEIFS(Table15[Survival],Table15[StartingSkills],FALSE,Table15[Gen],"="&Table74[[#This Row],[Generation]])/1000 -> 78.374833 | E32: {=_xlfn.STDEV.S(_xlfn._xlws.FILTER(Table15[Survival],(Table15[StartingSkills]=FALSE)*(Table15[Gen]=Table74[[#This Row],[Generation]])))/1000} -> 25.624994
A33: 8 | B33: =AVERAGEIFS(Table15[Survival],Table15[StartingSkills],TRUE,Table15[Gen],"="&Table74[[#This Row],[Generation]])/1000 -> 75.9567 | C33: {=_xlfn.STDEV.S(_xlfn._xlws.FILTER(Table15[Survival],(Table15[StartingSkills]=TRUE)*(Table15[Gen]=Table74[[#This Row],[Generation]])))/1000} -> 31.166557 | D33: =AVERAGEIFS(Table15[Survival],Table15[StartingSkills],FALSE,Table15[Gen],"="&Table74[[#This Row],[Generation]])/1000 -> 66.0555 | E33: {=_xlfn.STDEV.S(_xlfn._xlws.FILTER(Table15[Survival],(Table15[StartingSkills]=FALSE)*(Table15[Gen]=Table74[[#This Row],[Generation]])))/1000} -> 21.777666
A34: 9 | B34: =AVERAGEIFS(Table15[Survival],Table15[StartingSkills],TRUE,Table15[Gen],"="&Table74[[#This Row],[Generation]])/1000 -> 74.5061 | C34: {=_xlfn.STDEV.S(_xlfn._xlws.FILTER(Table15[Survival],(Table15[StartingSkills]=TRUE)*(Table15[Gen]=Table74[[#This Row],[Generation]])))/1000} -> 19.595812 | D34: =AVERAGEIFS(Table15[Survival],Table15[StartingSkills],FALSE,Table15[Gen],"="&Table74[[#This Row],[Generation]])/1000 -> 80.9765 | E34: {=_xlfn.STDEV.S(_xlfn._xlws.FILTER(Table15[Survival],(Table15[StartingSkills]=FALSE)*(Table15[Gen]=Table74[[#This Row],[Generation]])))/1000} -> 29.872835
A35: 10 | B35: =AVERAGEIFS(Table15[Survival],Table15[StartingSkills],TRUE,Table15[Gen],"="&Table74[[#This Row],[Generation]])/1000 -> 79.9667 | C35: {=_xlfn.STDEV.S(_xlfn._xlws.FILTER(Table15[Survival],(Table15[StartingSkills]=TRUE)*(Table15[Gen]=Table74[[#This Row],[Generation]])))/1000} -> 11.53076 | D35: =AVERAGEIFS(Table15[Survival],Table15[StartingSkills],FALSE,Table15[Gen],"="&Table74[[#This Row],[Generation]])/1000 -> 79.24625 | E35: {=_xlfn.STDEV.S(_xlfn._xlws.FILTER(Table15[Survival],(Table15[StartingSkills]=FALSE)*(Table15[Gen]=Table74[[#This Row],[Generation]])))/1000} -> 17.474376
A36: 11 | B36: =AVERAGEIFS(Table15[Survival],Table15[StartingSkills],TRUE,Table15[Gen],"="&Table74[[#This Row],[Generation]])/1000 -> 83.925667 | C36: {=_xlfn.STDEV.S(_xlfn._xlws.FILTER(Table15[Survival],(Table15[StartingSkills]=TRUE)*(Table15[Gen]=Table74[[#This Row],[Generation]])))/1000} -> 13.20822 | D36: =AVERAGEIFS(Table15[Survival],Table15[StartingSkills],FALSE,Table15[Gen],"="&Table74[[#This Row],[Generation]])/1000 -> 82.83175 | E36: {=_xlfn.STDEV.S(_xlfn._xlws.FILTER(Table15[Survival],(Table15[StartingSkills]=FALSE)*(Table15[Gen]=Table74[[#This Row],[Generation]])))/1000} -> 46.551314
A37: 12 | B37: =AVERAGEIFS(Table15[Survival],Table15[StartingSkills],TRUE,Table15[Gen],"="&Table74[[#This Row],[Generation]])/1000 -> 82.287 | C37: {=_xlfn.STDEV.S(_xlfn._xlws.FILTER(Table15[Survival],(Table15[StartingSkills]=TRUE)*(Table15[Gen]=Table74[[#This Row],[Generation]])))/1000} -> 25.13674 | D37: =AVERAGEIFS(Table15[Survival],Table15[StartingSkills],FALSE,Table15[Gen],"="&Table74[[#This Row],[Generation]])/1000 -> 90.0575 | E37: {=_xlfn.STDEV.S(_xlfn._xlws.FILTER(Table15[Survival],(Table15[StartingSkills]=FALSE)*(Table15[Gen]=Table74[[#This Row],[Generation]])))/1000} -> 24.579032
... A45: 20 | B45: =AVERAGEIFS(Table15[Survival],Table15[StartingSkills],TRUE,Table15[Gen],"="&Table74[[#This Row],[Generation]])/1000 -> 79.26075 | C45: {=_xlfn.STDEV.S(_xlfn._xlws.FILTER(Table15[Survival],(Table15[StartingSkills]=TRUE)*(Table15[Gen]=Table74[[#This Row],[Generation]])))/1000} -> 12.92273 | D45: =AVERAGEIFS(Table15[Survival],Table15[StartingSkills],FALSE,Table15[Gen],"="&Table74[[#This Row],[Generation]])/1000 -> 70.46175 | E45: {=_xlfn.STDEV.S(_xlfn._xlws.FILTER(Table15[Survival],(Table15[StartingSkills]=FALSE)*(Table15[Gen]=Table74[[#This Row],[Generation]])))/1000} -> 1.9887378
A49: Generation | B49: Skills generated | C49: Skills generated std
A50: 1 | B50: =AVERAGEIFS(Table15[SkillsGen],Table15[StartingSkills],FALSE,Table15[Gen],"="&Table746[[#This Row],[Generation]]) -> 3.6666667 | C50: {=_xlfn.STDEV.S(_xlfn._xlws.FILTER(Table15[SkillsGen],(Table15[StartingSkills]=FALSE)*(Table15[Gen]=Table746[[#This Row],[Generation]])))} -> 1.2110601
A51: 2 | B51: =AVERAGEIFS(Table15[SkillsGen],Table15[StartingSkills],FALSE,Table15[Gen],"="&Table746[[#This Row],[Generation]]) -> 2.3333333 | C51: {=_xlfn.STDEV.S(_xlfn._xlws.FILTER(Table15[SkillsGen],(Table15[StartingSkills]=FALSE)*(Table15[Gen]=Table746[[#This Row],[Generation]])))} -> 0.51639778
A52: 3 | B52: =AVERAGEIFS(Table15[SkillsGen],Table15[StartingSkills],FALSE,Table15[Gen],"="&Table746[[#This Row],[Generation]]) -> 1.6666667 | C52: {=_xlfn.STDEV.S(_xlfn._xlws.FILTER(Table15[SkillsGen],(Table15[StartingSkills]=FALSE)*(Table15[Gen]=Table746[[#This Row],[Generation]])))} -> 1.2110601
A53: 4 | B53: =AVERAGEIFS(Table15[SkillsGen],Table15[StartingSkills],FALSE,Table15[Gen],"="&Table746[[#This Row],[Generation]]) -> 0.6 | C53: {=_xlfn.STDEV.S(_xlfn._xlws.FILTER(Table15[SkillsGen],(Table15[StartingSkills]=FALSE)*(Table15[Gen]=Table746[[#This Row],[Generation]])))} -> 0.54772256
A54: 5 | B54: =AVERAGEIFS(Table15[SkillsGen],Table15[StartingSkills],FALSE,Table15[Gen],"="&Table746[[#This Row],[Generation]]) -> 2.5 | C54: {=_xlfn.STDEV.S(_xlfn._xlws.FILTER(Table15[SkillsGen],(Table15[StartingSkills]=FALSE)*(Table15[Gen]=Table746[[#This Row],[Generation]])))} -> 2.081666
A55: 6 | B55: =AVERAGEIFS(Table15[SkillsGen],Table15[StartingSkills],FALSE,Table15[Gen],"="&Table746[[#This Row],[Generation]]) -> 1.3333333 | C55: {=_xlfn.STDEV.S(_xlfn._xlws.FILTER(Table15[SkillsGen],(Table15[StartingSkills]=FALSE)*(Table15[Gen]=Table746[[#This Row],[Generation]])))} -> 0.57735027
A56: 7 | B56: =AVERAGEIFS(Table15[SkillsGen],Table15[StartingSkills],FALSE,Table15[Gen],"="&Table746[[#This Row],[Generation]]) -> 3.3333333 | C56: {=_xlfn.STDEV.S(_xlfn._xlws.FILTER(Table15[SkillsGen],(Table15[StartingSkills]=FALSE)*(Table15[Gen]=Table746[[#This Row],[Generation]])))} -> 4.0414519
A57: 8 | B57: =AVERAGEIFS(Table15[SkillsGen],Table15[StartingSkills],FALSE,Table15[Gen],"="&Table746[[#This Row],[Generation]]) -> 0.33333333 | C57: {=_xlfn.STDEV.S(_xlfn._xlws.FILTER(Table15[SkillsGen],(Table15[StartingSkills]=FALSE)*(Table15[Gen]=Table746[[#This Row],[Generation]])))} -> 0.57735027
A58: 9 | B58: =AVERAGEIFS(Table15[SkillsGen],Table15[StartingSkills],FALSE,Table15[Gen],"="&Table746[[#This Row],[Generation]]) -> 1 | C58: {=_xlfn.STDEV.S(_xlfn._xlws.FILTER(Table15[SkillsGen],(Table15[StartingSkills]=FALSE)*(Table15[Gen]=Table746[[#This Row],[Generation]])))} -> 1
A59: 10 | B59: =AVERAGEIFS(Table15[SkillsGen],Table15[StartingSkills],FALSE,Table15[Gen],"="&Table746[[#This Row],[Generation]]) -> 1 | C59: {=_xlfn.STDEV.S(_xlfn._xlws.FILTER(Table15[SkillsGen],(Table15[StartingSkills]=FALSE)*(Table15[Gen]=Table746[[#This Row],[Generation]])))} -> 0
A60: 11 | B60: =AVERAGEIFS(Table15[SkillsGen],Table15[StartingSkills],FALSE,Table15[Gen],"="&Table746[[#This Row],[Generation]]) -> 0 | C60: {=_xlfn.STDEV.S(_xlfn._xlws.FILTER(Table15[SkillsGen],(Table15[StartingSkills]=FALSE)*(Table15[Gen]=Table746[[#This Row],[Generation]])))} -> 0
...

Sheet Sheet3
A1: Category | B1: Skill Name | C1: Times Made | D1: Times Executed | H1: Skill Category | I1: Total Times Made | J1: Total Times Executed
A2: Combat - Offensive | B2: attack_hostile_by_id | C2: 3 | D2: 44 | H2: Melee Combat | I2: 11 | J2: 1379
B3: attack_hostile_with_bow | C3: 1 | D3: 0 | H3: attack_hostile_by_id, attack_nearest_hostile, flank_and_attack_hostile, melee_attack, melee_attack_closest_hostile, melee_attack_forward, melee_attack_nearest_hostile
B4: attack_nearest_hostile | C4: 3 | D4: 175 | H4: Ranged Combat | I4: 5 | J4: 529
B5: attack_with_bow | C5: 1 | D5: 0 | H5: attack_hostile_with_bow, attack_with_bow, bow_attack, ranged_attack_nearest_hostile, shoot_arrow_at_hostile, shoot_zombie
B6: bow_attack | C6: 0 | D6: 521 | H6: Kiting & Positioning | I6: 16 | J6: 324
B7: flank_and_attack_hostile | C7: 1 | D7: 1 | H7: defend_from_multiple_hosts, defensive_positioning, establish_defensive_position, kite_and_retreat, kite_and_shoot, kite_bot1, kite_nearest_hostile, kite_zombie_nearby, kneel_and_defend, maintain_line_of_sight
B8: melee_attack | C8: 1 | D8: 1145 | H8: Retreat & Evade | I8: 10 | J8: 73
B9: melee_attack_closest_hostile | C9: 1 | D9: 0 | H9: panic_retreat_and_block, retreat_50_blocks, retreat_and_eat, retreat_to_safety, retreat_while_eating, safety_retreat
B10: melee_attack_forward | C10: 1 | D10: 14 | H10: Building Defenses | I10: 20 | J10: 42
B11: melee_attack_nearest_hostile | C11: 1 | D11: 0 | H11: build_2x2_shelter, build_2x2_wall, build_barricade, build_cover, build_defensive_pillar, build_defensive_structure, build_defensive_wall, build_pillar_3, build_wall_2x2, emergency_box, full_box, place_cover, place_defensive_barrier, place_oak_plank, place_oak_planks, place_oak_planks_barrier, shelter_with_planks
B12: ranged_attack_nearest_hostile | C12: 1 | D12: 5 | H12: Navigation | I12: 17 | J12: 408
B13: shoot_arrow_at_hostile | C13: 1 | D13: 0 | H13: establish_patrol_position, move_scout_area, move_to_coordinate, move_to_gathering_point, move_to_midpoint, move_to_midpoint_with_bot1, move_to_player, move_to_spawn_midpoint, patrol_area, scout_random_direction, scout_randomly
B14: shoot_zombie | C14: 1 | D14: 3 | H14: Healing (Eating) | I14: 6 | J14: 790
A15: Combat - Defensive & Tactical | B15: defend_from_multiple_hosts | C15: 1 | D15: 47 | H15: eat_bread, eat_bread_safe, eat_bread_until_full, eat_food, eat_food_if_hungry_or_hurt
B16: defensive_positioning | C16: 1 | D16: 0 | H16: Equipment Management | I16: 8 | J16: 707
B17: establish_defensive_position | C17: 2 | D17: 24 | H17: equip_best_armor, equip_best_gear, equip_chestplate, equip_gear, equip_item_in_hand, equip_leather_armor, equip_leather_tunic, wear_armor
B18: kite_and_retreat | C18: 1 | D18: 2 | H18: Item Management | I18: 6 | J18: 21
B19: kite_and_shoot | C19: 1 | D19: 0 | H19: drop_bread, drop_bread_for_teammate, drop_bread_nearby, pick_up_item, send_bread_to_player
B20: kite_bot1 | C20: 1 | D20: 30 | H20: Communication & Utility | I20: 2 | J20: 1548
B21: kite_nearest_hostile | C21: 6 | D21: 159 | H21: do_nothing, new_action, send_message, identify_remaining_hostiles, report_teammate_death
B22: kite_zombie_nearby | C22: 1 | D22: 0
B23: kneel_and_defend | C23: 1 | D23: 5
B24: maintain_line_of_sight | C24: 1 | D24: 57
B25: panic_retreat_and_block | C25: 3 | D25: 9
B26: retreat_50_blocks | C26: 1 | D26: 0
B27: retreat_and_eat | C27: 1 | D27: 0
B28: retreat_to_safety | C28: 1 | D28: 35
B29: retreat_while_eating | C29: 1 | D29: 14
B30: safety_retreat | C30: 3 | D30: 15
A31: Building & Structures | B31: build_2x2_shelter | C31: 1 | D31: 12
B32: build_2x2_wall | C32: 1 | D32: 0
B33: build_barricade | C33: 1 | D33: 4
B34: build_cover | C34: 1 | D34: 11
B35: build_defensive_pillar | C35: 2 | D35: 10
B36: build_defensive_structure | C36: 1 | D36: 2
B37: build_defensive_wall | C37: 3 | D37: 2
B38: build_pillar_3 | C38: 1 | D38: 0
B39: build_wall_2x2 | C39: 1 | D39: 0
B40: emergency_box | C40: 1 | D40: 1
...

Sheet starting skills

Sheet Skills
A1: ID | B1: Lineage | C1: Gen | D1: Skills generated | E1: Note
A2: =Table2[[#This Row],[Lineage]]&"-"&Table2[[#This Row],[Gen]] -> 3-3 | B2: 3 | C2: 3 | D2: 1 | E2: 3 generationLine1
A3: =Table2[[#This Row],[Lineage]]&"-"&Table2[[#This Row],[Gen]] -> 4-2 | B3: 4 | C3: 2 | D3: 1 | E3: 4 generationLine2
A4: =Table2[[#This Row],[Lineage]]&"-"&Table2[[#This Row],[Gen]] -> 5-6 | B4: 5 | C4: 6 | D4: 2 | E4: 5 generationLine3
A5: =Table2[[#This Row],[Lineage]]&"-"&Table2[[#This Row],[Gen]] -> 6-4 | B5: 6 | C5: 4 | D5: 1 | E5: 6 generationLine4
A6: =Table2[[#This Row],[Lineage]]&"-"&Table2[[#This Row],[Gen]] -> 7-1 | B6: 7 | C6: 1 | D6: 1 | E6: 7 generationLine5
A7: =Table2[[#This Row],[Lineage]]&"-"&Table2[[#This Row],[Gen]] -> 8-3 | B7: 8 | C7: 3 | D7: 1 | E7: 8 generationLine6
A8: =Table2[[#This Row],[Lineage]]&"-"&Table2[[#This Row],[Gen]] -> 9-1 | B8: 9 | C8: 1 | D8: 3 | E8: 9 generationLine7
A9: =Table2[[#This Row],[Lineage]]&"-"&Table2[[#This Row],[Gen]] -> 9-2 | B9: 9 | C9: 2 | D9: 2 | E9: 9 generationLine7
A10: =Table2[[#This Row],[Lineage]]&"-"&Table2[[#This Row],[Gen]] -> 9-3 | B10: 9 | C10: 3 | D10: 1 | E10: 9 generationLine7
A11: =Table2[[#This Row],[Lineage]]&"-"&Table2[[#This Row],[Gen]] -> 9-5 | B11: 9 | C11: 5 | D11: 3 | E11: 9 generationLine7
A12: =Table2[[#This Row],[Lineage]]&"-"&Table2[[#This Row],[Gen]] -> 9-6 | B12: 9 | C12: 6 | D12: 1 | E12: 9 generationLine7
A13: =Table2[[#This Row],[Lineage]]&"-"&Table2[[#This Row],[Gen]] -> 9-7 | B13: 9 | C13: 7 | D13: 1 | E13: 9 generationLine7
... A55: =Table2[[#This Row],[Lineage]]&"-"&Table2[[#This Row],[Gen]] -> 23-4 | B55: 23 | C55: 4 | D55: 1 | E55: 23 Real Run 13 - State of the art

Sheet Sheet4
E4: Skill Category | F4: Total Times Generated | G4: Total Times Executed | H4: Skills Generated
E5: Melee Combat | F5: 11 | G5: 1379 | H5: attack_hostile_by_id, attack_nearest_hostile, flank_and_attack_hostile, melee_attack, melee_attack_closest_hostile, melee_attack_forward, melee_attack_nearest_hostile
E6: Ranged Combat | F6: 5 | G6: 529 | H6: attack_hostile_with_bow, attack_with_bow, bow_attack, ranged_attack_nearest_hostile, shoot_arrow_at_hostile, shoot_zombie
E7: Kiting & Positioning | F7: 16 | G7: 324 | H7: defend_from_multiple_hosts, defensive_positioning, establish_defensive_position, kite_and_retreat, kite_and_shoot, kite_bot1, kite_nearest_hostile, kite_zombie_nearby, kneel_and_defend, maintain_line_of_sight
E8: Retreat & Evade | F8: 10 | G8: 73 | H8: panic_retreat_and_block, retreat_50_blocks, retreat_and_eat, retreat_to_safety, retreat_while_eating, safety_retreat
E9: Building Defenses | F9: 20 | G9: 42 | H9: build_2x2_shelter, build_2x2_wall, build_barricade, build_cover, build_defensive_pillar, build_defensive_structure, build_defensive_wall, build_pillar_3, build_wall_2x2, emergency_box, full_box, place_cover, place_defensive_barrier, place_oak_plank, place_oak_planks, place_oak_planks_barrier, shelter_with_planks
E10: Navigation | F10: 17 | G10: 408 | H10: establish_patrol_position, move_scout_area, move_to_coordinate, move_to_gathering_point, move_to_midpoint, move_to_midpoint_with_bot1, move_to_player, move_to_spawn_midpoint, patrol_area, scout_random_direction, scout_randomly
E11: Healing (Eating) | F11: 6 | G11: 790 | H11: eat_bread, eat_bread_safe, eat_bread_until_full, eat_food, eat_food_if_hungry_or_hurt
E12: Equipment Management | F12: 8 | G12: 707 | H12: equip_best_armor, equip_best_gear, equip_chestplate, equip_gear, equip_item_in_hand, equip_leather_armor, equip_leather_tunic, wear_armor
E13: Item Management | F13: 6 | G13: 21 | H13: drop_bread, drop_bread_for_teammate, drop_bread_nearby, pick_up_item, send_bread_to_player
E14: Communication & Utility | F14: 2 | G14: 1548 | H14: do_nothing, new_action, send_message, identify_remaining_hostiles, report_teammate_death

Sheet All skills
F5: Skill Category | G5: Total Times Generated | H5: Total Times Executed | K5: Skill Name | L5: Skill Category | M5: Total Times Generated | N5: Total Times Executed
F6: Melee Combat | G6: 11 | H6: 1379 | K6: build_2x2_shelter | L6: Building Defenses | M6: 1 | N6: 12
F7: Ranged Combat | G7: 5 | H7: 529 | K7: build_2x2_wall | L7: Building Defenses | M7: 1 | N7: 0
F8: Kiting & Positioning | G8: 16 | H8: 324 | K8: build_barricade | L8: Building Defenses | M8: 1 | N8: 4
F9: Retreat & Evade | G9: 10 | H9: 73 | K9: build_cover | L9: Building Defenses | M9: 1 | N9: 11
F10: Building Defenses | G10: 20 | H10: 42 | K10: build_defensive_pillar | L10: Building Defenses | M10: 2 | N10: 10
F11: Navigation | G11: 17 | H11: 408 | K11: build_defensive_structure | L11: Building Defenses | M11: 1 | N11: 2
F12: Healing (Eating) | G12: 6 | H12: 790 | K12: build_defensive_wall | L12: Building Defenses | M12: 3 | N12: 2
F13: Equipment Management | G13: 8 | H13: 707 | K13: build_pillar_3 | L13: Building Defenses | M13: 1 | N13: 0
F14: Item Management | G14: 6 | H14: 21 | K14: build_wall_2x2 | L14: Building Defenses | M14: 1 | N14: 0
F15: Communication & Utility | G15: 2 | H15: 1548 | K15: emergency_box | L15: Building Defenses | M15: 1 | N15: 1
K16: full_box | L16: Building Defenses | M16: 1 | N16: 0
K17: place_cover | L17: Building Defenses | M17: 1 | N17: 0
K18: place_defensive_barrier | L18: Building Defenses | M18: 1 | N18: 0
F19: Skill Category | G19: Total Times Generated | H19: Total Times Executed | K19: place_oak_plank | L19: Building Defenses | M19: 1 | N19: 0
F20: Melee Combat | G20: =SUMIF(Table6[Skill Category],F20,Table6[Total Times Generated]) -> 14 | H20: =SUMIF(Table6[Skill Category],F20,Table6[Total Times Executed]) -> 1431 | K20: place_oak_planks | L20: Building Defenses | M20: 1 | N20: 0
F21: Ranged Combat | G21: =SUMIF(Table6[Skill Category],F21,Table6[Total Times Generated]) -> 6 | H21: =SUMIF(Table6[Skill Category],F21,Table6[Total Times Executed]) -> 529 | K21: place_oak_planks_barrier | L21: Building Defenses | M21: 1 | N21: 0
F22: Building Defenses | G22: =SUMIF(Table6[Skill Category],F22,Table6[Total Times Generated]) -> 20 | H22: =SUMIF(Table6[Skill Category],F22,Table6[Total Times Executed]) -> 42 | K22: shelter_with_planks | L22: Building Defenses | M22: 1 | N22: 0
F23: Navigation | G23: =SUMIF(Table6[Skill Category],F23,Table6[Total Times Generated]) -> 39 | H23: =SUMIF(Table6[Skill Category],F23,Table6[Total Times Executed]) -> 753 | K23: do_nothing | L23: Communication & Utility | M23: 0 | N23: 286
F24: Healing (Eating) | G24: =SUMIF(Table6[Skill Category],F24,Table6[Total Times Generated]) -> 6 | H24: =SUMIF(Table6[Skill Category],F24,Table6[Total Times Executed]) -> 790 | K24: identify_remaining_hostiles | L24: Communication & Utility | M24: 1 | N24: 0
F25: Equipment Management | G25: =SUMIF(Table6[Skill Category],F25,Table6[Total Times Generated]) -> 8 | H25: =SUMIF(Table6[Skill Category],F25,Table6[Total Times Executed]) -> 707 | K25: new_action | L25: Communication & Utility | M25: 0 | N25: 130
F26: Item Management | G26: =SUMIF(Table6[Skill Category],F26,Table6[Total Times Generated]) -> 6 | H26: =SUMIF(Table6[Skill Category],F26,Table6[Total Times Executed]) -> 21 | K26: report_teammate_death | L26: Communication & Utility | M26: 1 | N26: 0
F27: Communication & Utility | G27: =SUMIF(Table6[Skill Category],F27,Table6[Total Times Generated]) -> 2 | H27: =SUMIF(Table6[Skill Category],F27,Table6[Total Times Executed]) -> 1548 | K27: send_message | L27: Communication & Utility | M27: 0 | N27: 1132
K28: equip_best_armor | L28: Equipment Management | M28: 1 | N28: 1
K29: equip_best_gear | L29: Equipment Management | M29: 1 | N29: 7
K30: equip_chestplate | L30: Equipment Management | M30: 1 | N30: 0
K31: equip_gear | L31: Equipment Management | M31: 0 | N31: 281
K32: equip_item_in_hand | L32: Equipment Management | M32: 0 | N32: 347
K33: equip_leather_armor | L33: Equipment Management | M33: 1 | N33: 0
K34: equip_leather_tunic | L34: Equipment Management | M34: 3 | N34: 55
K35: wear_armor | L35: Equipment Management | M35: 1 | N35: 16
K36: eat_bread | L36: Healing (Eating) | M36: 3 | N36: 128
K37: eat_bread_safe | L37: Healing (Eating) | M37: 1 | N37: 0
K38: eat_bread_until_full | L38: Healing (Eating) | M38: 0 | N38: 587
K39: eat_food | L39: Healing (Eating) | M39: 1 | N39: 72
... K85: safety_retreat | L85: Navigation | M85: 3 | N85: 15

Sheet No starting skills
F5: Skill Category | G5: Total Times Generated | H5: Total Times Executed | K5: Skill Name | L5: Skill Category | M5: Total Times Generated | N5: Total Times Executed
F6: Melee Combat | G6: 11 | H6: 1379 | K6: build_2x2_shelter | L6: Building Defenses | M6: 1 | N6: 12
F7: Ranged Combat | G7: 5 | H7: 529 | K7: build_2x2_wall | L7: Building Defenses | M7: 1 | N7: 0
F8: Kiting & Positioning | G8: 16 | H8: 324 | K8: build_barricade | L8: Building Defenses | M8: 1 | N8: 4
F9: Retreat & Evade | G9: 10 | H9: 73 | K9: build_cover | L9: Building Defenses | M9: 1 | N9: 11
F10: Building Defenses | G10: 20 | H10: 42 | K10: build_defensive_pillar | L10: Building Defenses | M10: 2 | N10: 10
F11: Navigation | G11: 17 | H11: 408 | K11: build_defensive_structure | L11: Building Defenses | M11: 1 | N11: 2
F12: Healing (Eating) | G12: 6 | H12: 790 | K12: build_defensive_wall | L12: Building Defenses | M12: 3 | N12: 2
F13: Equipment Management | G13: 8 | H13: 707 | K13: build_pillar_3 | L13: Building Defenses | M13: 1 | N13: 0
F14: Item Management | G14: 6 | H14: 21 | K14: build_wall_2x2 | L14: Building Defenses | M14: 1 | N14: 0
F15: Communication & Utility | G15: 2 | H15: 1548 | K15: emergency_box | L15: Building Defenses | M15: 1 | N15: 1
K16: full_box | L16: Building Defenses | M16: 1 | N16: 0
K17: place_cover | L17: Building Defenses | M17: 1 | N17: 0
K18: place_defensive_barrier | L18: Building Defenses | M18: 1 | N18: 0
F19: Skill Category | G19: Total Times Generated | H19: Total Times Executed | K19: place_oak_plank | L19: Building Defenses | M19: 1 | N19: 0
F20: Melee Combat | G20: =SUMIF(Table69[Skill Category],F20,Table69[Total Times Generated]) -> 14 | H20: =SUMIF(Table69[Skill Category],F20,Table69[Total Times Executed]) -> 293 | K20: place_oak_planks | L20: Building Defenses | M20: 1 | N20: 0
